<robot name="onshape">
    <mujoco>
        <compiler fusestatic="false" inertiafromgeom="false" />
    </mujoco>
    <link name="part_1">
        <visual>
            <origin xyz="0.0486492 -0.243547 0.472363" rpy="-4.20795e-16 0.0723492 -4.76065e-16" />
            <geometry>
                <mesh filename="package:///part_1.stl" />
            </geometry>
            <material name="part_1_material">
                <color rgba="0.231373 0.380392 0.705882 1.0" />
            </material>
        </visual>
        <collision>
            <origin xyz="0.0486492 -0.243547 0.472363" rpy="-4.20795e-16 0.0723492 -4.76065e-16" />
            <geometry>
                <mesh filename="package:///part_1.stl" />
            </geometry>
            <material name="part_1_material">
                <color rgba="0.231373 0.380392 0.705882 1.0" />
            </material>
        </collision>
        <inertial>
            <origin xyz="0.0499504 -0.243547 0.490316" rpy="0 0 0" />
            <mass value="1.4693" />
            <inertia ixx="0.00120565" ixy="4.43755e-19" ixz="0.000140465" iyy="0.00226565" iyz="2.87468e-19" izz="0.00313357" />
        </inertial>
    </link>

    <link name="arm5">
        <visual>
            <origin xyz="0.0455 0.0205 0.019" rpy="1.5708 1.30722e-32 1.11764e-32" />
            <geometry>
                <mesh filename="package:///arm5.stl" />
            </geometry>
            <material name="arm5_material">
                <color rgba="0.647059 0.647059 0.647059 1.0" />
            </material>
        </visual>
        <collision>
            <origin xyz="0.0455 0.0205 0.019" rpy="1.5708 1.30722e-32 1.11764e-32" />
            <geometry>
                <mesh filename="package:///arm5.stl" />
            </geometry>
            <material name="arm5_material">
                <color rgba="0.647059 0.647059 0.647059 1.0" />
            </material>
        </collision>
        <inertial>
            <origin xyz="-0.00577778 0 0.019" rpy="0 0 0" />
            <mass value="0.0156937" />
            <inertia ixx="5.06341e-06" ixy="6.99671e-38" ixz="-1.11262e-37" iyy="5.35559e-06" iyz="4.82802e-23" izz="1.92694e-06" />
        </inertial>
    </link>

    <link name="arm4">
        <visual>
            <origin xyz="0 -0.0205 0.06" rpy="-1.5708 -1.5708 0" />
            <geometry>
                <mesh filename="package:///arm4.stl" />
            </geometry>
            <material name="arm4_material">
                <color rgba="0.972549 0.529412 0.00392157 1.0" />
            </material>
        </visual>
        <collision>
            <origin xyz="0 -0.0205 0.06" rpy="-1.5708 -1.5708 0" />
            <geometry>
                <mesh filename="package:///arm4.stl" />
            </geometry>
            <material name="arm4_material">
                <color rgba="0.972549 0.529412 0.00392157 1.0" />
            </material>
        </collision>
        <inertial>
            <origin xyz="-0.0130017 -3.46945e-18 -0.0385551" rpy="0 0 0" />
            <mass value="0.304573" />
            <inertia ixx="0.000140255" ixy="-4.67027e-21" ixz="1.36899e-06" iyy="0.000182801" iyz="-3.06297e-24" izz="6.25553e-05" />
        </inertial>
    </link>

    <link name="arm3">
        <visual>
            <origin xyz="0.115 5.55112e-17 -0.004" rpy="-3.99421e-19 -2.22627e-18 -8.61849e-18" />
            <geometry>
                <mesh filename="package:///arm3.stl" />
            </geometry>
            <material name="arm3_material">
                <color rgba="0.231373 0.380392 0.705882 1.0" />
            </material>
        </visual>
        <collision>
            <origin xyz="0.115 5.55112e-17 -0.004" rpy="-3.99421e-19 -2.22627e-18 -8.61849e-18" />
            <geometry>
                <mesh filename="package:///arm3.stl" />
            </geometry>
            <material name="arm3_material">
                <color rgba="0.231373 0.380392 0.705882 1.0" />
            </material>
        </collision>
        <inertial>
            <origin xyz="0.0164728 0.0533065 0.0165" rpy="0 0 0" />
            <mass value="0.253495" />
            <inertia ixx="0.000378964" ixy="-0.000135069" ixz="6.63969e-21" iyy="0.00020759" iyz="-4.08699e-22" izz="0.000429282" />
        </inertial>
    </link>

    <link name="arm2">
        <visual>
            <origin xyz="0.0633934 0.0959494 0.005" rpy="-3.14159 -4.67048e-18 -8.38343e-17" />
            <geometry>
                <mesh filename="package:///arm2.stl" />
            </geometry>
            <material name="arm2_material">
                <color rgba="0.768627 0.886275 0.952941 1.0" />
            </material>
        </visual>
        <collision>
            <origin xyz="0.0633934 0.0959494 0.005" rpy="-3.14159 -4.67048e-18 -8.38343e-17" />
            <geometry>
                <mesh filename="package:///arm2.stl" />
            </geometry>
            <material name="arm2_material">
                <color rgba="0.768627 0.886275 0.952941 1.0" />
            </material>
        </collision>
        <inertial>
            <origin xyz="0.0535692 -0.0124398 -0.0155" rpy="0 0 0" />
            <mass value="0.582673" />
            <inertia ixx="0.000143067" ixy="8.86254e-05" ixz="1.14604e-20" iyy="0.00111301" iyz="1.00742e-20" izz="0.00114357" />
        </inertial>
    </link>

    <link name="arm1">
        <visual>
            <origin xyz="-0.0452202 -0.106044 -0.004" rpy="1.70535e-19 4.71056e-18 1.84856e-17" />
            <geometry>
                <mesh filename="package:///arm1.stl" />
            </geometry>
            <material name="arm1_material">
                <color rgba="0.917647 0.917647 0.917647 1.0" />
            </material>
        </visual>
        <collision>
            <origin xyz="-0.0452202 -0.106044 -0.004" rpy="1.70535e-19 4.71056e-18 1.84856e-17" />
            <geometry>
                <mesh filename="package:///arm1.stl" />
            </geometry>
            <material name="arm1_material">
                <color rgba="0.917647 0.917647 0.917647 1.0" />
            </material>
        </collision>
        <inertial>
            <origin xyz="0.0422881 -0.0309098 0.0165" rpy="0 0 0" />
            <mass value="0.226307" />
            <inertia ixx="0.000293317" ixy="0.000172327" ixz="-1.48314e-21" iyy="0.000261614" iyz="-7.09909e-22" izz="0.000421982" />
        </inertial>
    </link>

    <joint name="11" type="revolute">
        <origin xyz="0.108614 -0.0100944 0.001" rpy="3.14159 4.95003e-17 -0.600525" />
        <parent link="arm2" />
        <child link="arm1" />
        <axis xyz="0 0 1" />
        <limit effort="1" velocity="20" lower="-1.0472" upper="1.0472" />
        <joint_properties friction="0.0" />
    </joint>

    <joint name="12" type="revolute">
        <origin xyz="0.0516066 0.0959494 0.001" rpy="3.14159 -6.92614e-16 -0.197577" />
        <parent link="arm3" />
        <child link="arm2" />
        <axis xyz="0 0 1" />
        <limit effort="1" velocity="20" lower="-1.0472" upper="1.0472" />
        <joint_properties friction="0.0" />
    </joint>

    <joint name="13" type="revolute">
        <origin xyz="0 -0.0165 -0.055" rpy="-1.5708 -0.326734 1.89868e-16" />
        <parent link="arm4" />
        <child link="arm3" />
        <axis xyz="0 0 1" />
        <limit effort="1" velocity="20" lower="0" upper="1.5708" />
        <joint_properties friction="0.0" />
    </joint>

    <joint name="14" type="revolute">
        <origin xyz="-0.0145 -3.46945e-18 0.019" rpy="-3.14159 -1.5708 0" />
        <parent link="arm5" />
        <child link="arm4" />
        <axis xyz="0 0 1" />
        <limit effort="1" velocity="20" lower="-3.14159" upper="0" />
        <joint_properties friction="0.0" />
    </joint>

    <joint name="1" type="revolute">
        <origin xyz="0.0113562 -0.205451 0.51116" rpy="3.06924 -4.2479e-16 -1.5708" />
        <parent link="part_1" />
        <child link="arm5" />
        <axis xyz="0 0 1" />
        <limit effort="1" velocity="20" lower="-1.5708" upper="0" />
        <joint_properties friction="0.0" />
    </joint>

    <link name="arm5_2">
        <visual>
            <origin xyz="0.0455 -0.0205 0.019" rpy="-1.5708 5.6604e-19 -1.70245e-18" />
            <geometry>
                <mesh filename="package:///arm5.stl" />
            </geometry>
            <material name="arm5_material">
                <color rgba="0.647059 0.647059 0.647059 1.0" />
            </material>
        </visual>
        <collision>
            <origin xyz="0.0455 -0.0205 0.019" rpy="-1.5708 5.6604e-19 -1.70245e-18" />
            <geometry>
                <mesh filename="package:///arm5.stl" />
            </geometry>
            <material name="arm5_material">
                <color rgba="0.647059 0.647059 0.647059 1.0" />
            </material>
        </collision>
        <inertial>
            <origin xyz="-0.00577778 2.42861e-17 0.019" rpy="0 0 0" />
            <mass value="0.0156937" />
            <inertia ixx="5.06341e-06" ixy="-2.15628e-22" ixz="-9.2817e-24" iyy="5.35559e-06" iyz="-3.97159e-23" izz="1.92694e-06" />
        </inertial>
    </link>

    <link name="arm4_2">
        <visual>
            <origin xyz="-5.55112e-17 -0.0205 0.06" rpy="-1.5708 -1.5708 0" />
            <geometry>
                <mesh filename="package:///arm4.stl" />
            </geometry>
            <material name="arm4_material">
                <color rgba="0.972549 0.529412 0.00392157 1.0" />
            </material>
        </visual>
        <collision>
            <origin xyz="-5.55112e-17 -0.0205 0.06" rpy="-1.5708 -1.5708 0" />
            <geometry>
                <mesh filename="package:///arm4.stl" />
            </geometry>
            <material name="arm4_material">
                <color rgba="0.972549 0.529412 0.00392157 1.0" />
            </material>
        </collision>
        <inertial>
            <origin xyz="-0.0130017 0 -0.0385551" rpy="0 0 0" />
            <mass value="0.304573" />
            <inertia ixx="0.000140255" ixy="-1.05191e-22" ixz="1.36899e-06" iyy="0.000182801" iyz="-3.40796e-21" izz="6.25553e-05" />
        </inertial>
    </link>

    <link name="arm3_2">
        <visual>
            <origin xyz="0.115 -5.55112e-17 0.037" rpy="3.14159 -4.57488e-19 -6.61483e-17" />
            <geometry>
                <mesh filename="package:///arm3.stl" />
            </geometry>
            <material name="arm3_material">
                <color rgba="0.231373 0.380392 0.705882 1.0" />
            </material>
        </visual>
        <collision>
            <origin xyz="0.115 -5.55112e-17 0.037" rpy="3.14159 -4.57488e-19 -6.61483e-17" />
            <geometry>
                <mesh filename="package:///arm3.stl" />
            </geometry>
            <material name="arm3_material">
                <color rgba="0.231373 0.380392 0.705882 1.0" />
            </material>
        </collision>
        <inertial>
            <origin xyz="0.0164728 -0.0533065 0.0165" rpy="0 0 0" />
            <mass value="0.253495" />
            <inertia ixx="0.000378964" ixy="0.000135069" ixz="-2.20927e-22" iyy="0.00020759" iyz="1.55703e-21" izz="0.000429282" />
        </inertial>
    </link>

    <link name="arm2_2">
        <visual>
            <origin xyz="0.0633934 -0.0959494 -0.036" rpy="-5.58119e-18 1.697e-18 -1.98839e-18" />
            <geometry>
                <mesh filename="package:///arm2.stl" />
            </geometry>
            <material name="arm2_material">
                <color rgba="0.768627 0.886275 0.952941 1.0" />
            </material>
        </visual>
        <collision>
            <origin xyz="0.0633934 -0.0959494 -0.036" rpy="-5.58119e-18 1.697e-18 -1.98839e-18" />
            <geometry>
                <mesh filename="package:///arm2.stl" />
            </geometry>
            <material name="arm2_material">
                <color rgba="0.768627 0.886275 0.952941 1.0" />
            </material>
        </collision>
        <inertial>
            <origin xyz="0.0535692 0.0124398 -0.0155" rpy="0 0 0" />
            <mass value="0.582673" />
            <inertia ixx="0.000143067" ixy="-8.86254e-05" ixz="1.72158e-20" iyy="0.00111301" iyz="-1.67853e-20" izz="0.00114357" />
        </inertial>
    </link>

    <link name="arm1_2">
        <visual>
            <origin xyz="-0.0452202 0.106044 0.037" rpy="3.14159 2.01685e-17 6.17901e-17" />
            <geometry>
                <mesh filename="package:///arm1.stl" />
            </geometry>
            <material name="arm1_material">
                <color rgba="0.917647 0.917647 0.917647 1.0" />
            </material>
        </visual>
        <collision>
            <origin xyz="-0.0452202 0.106044 0.037" rpy="3.14159 2.01685e-17 6.17901e-17" />
            <geometry>
                <mesh filename="package:///arm1.stl" />
            </geometry>
            <material name="arm1_material">
                <color rgba="0.917647 0.917647 0.917647 1.0" />
            </material>
        </collision>
        <inertial>
            <origin xyz="0.0422881 0.0309098 0.0165" rpy="0 0 0" />
            <mass value="0.226307" />
            <inertia ixx="0.000293317" ixy="-0.000172327" ixz="-4.55533e-21" iyy="0.000261614" iyz="-8.16389e-23" izz="0.000421982" />
        </inertial>
    </link>

    <joint name="21" type="revolute">
        <origin xyz="0.108614 0.0100944 0.001" rpy="-3.14159 2.14604e-15 1.04712" />
        <parent link="arm2_2" />
        <child link="arm1_2" />
        <axis xyz="0 0 1" />
        <limit effort="1" velocity="20" lower="-1.0472" upper="1.0472" />
        <joint_properties friction="0.0" />
    </joint>

    <joint name="22" type="revolute">
        <origin xyz="0.0516066 -0.0959494 0.001" rpy="3.14159 -7.3473e-16 0.198362" />
        <parent link="arm3_2" />
        <child link="arm2_2" />
        <axis xyz="0 0 1" />
        <limit effort="1" velocity="20" lower="-1.0472" upper="1.0472" />
        <joint_properties friction="0.0" />
    </joint>

    <joint name="23" type="revolute">
        <origin xyz="0 0.0165 -0.055" rpy="1.5708 -0.401154 -2.98208e-16" />
        <parent link="arm4_2" />
        <child link="arm3_2" />
        <axis xyz="0 0 1" />
        <limit effort="1" velocity="20" lower="-1.5708" upper="0" />
        <joint_properties friction="0.0" />
    </joint>

    <joint name="24" type="revolute">
        <origin xyz="-0.0145 5.55112e-17 0.019" rpy="-1.5708 -1.49113 -1.5708" />
        <parent link="arm5_2" />
        <child link="arm4_2" />
        <axis xyz="0 0 1" />
        <limit effort="1" velocity="20" lower="-3.14159" upper="-0.0174533" />
        <joint_properties friction="0.0" />
    </joint>

    <joint name="2" type="revolute">
        <origin xyz="0.0911469 -0.205451 0.505377" rpy="3.07168 -0.0186424 -1.83097" />
        <parent link="part_1" />
        <child link="arm5_2" />
        <axis xyz="0 0 1" />
        <limit effort="1" velocity="20" lower="0" upper="1.5708" />
        <joint_properties friction="0.0" />
    </joint>

    <link name="arm5_3">
        <visual>
            <origin xyz="0.0455 -0.0205 0.019" rpy="-1.5708 -7.03005e-32 -1.36342e-31" />
            <geometry>
                <mesh filename="package:///arm5.stl" />
            </geometry>
            <material name="arm5_material">
                <color rgba="0.647059 0.647059 0.647059 1.0" />
            </material>
        </visual>
        <collision>
            <origin xyz="0.0455 -0.0205 0.019" rpy="-1.5708 -7.03005e-32 -1.36342e-31" />
            <geometry>
                <mesh filename="package:///arm5.stl" />
            </geometry>
            <material name="arm5_material">
                <color rgba="0.647059 0.647059 0.647059 1.0" />
            </material>
        </collision>
        <inertial>
            <origin xyz="-0.00577778 6.93889e-18 0.019" rpy="0 0 0" />
            <mass value="0.0156937" />
            <inertia ixx="5.06341e-06" ixy="-3.00338e-36" ixz="5.55464e-37" iyy="5.35559e-06" iyz="-6.16047e-23" izz="1.92694e-06" />
        </inertial>
    </link>

    <link name="arm4_3">
        <visual>
            <origin xyz="0 -0.0205 0.06" rpy="-1.5708 -1.5708 0" />
            <geometry>
                <mesh filename="package:///arm4.stl" />
            </geometry>
            <material name="arm4_material">
                <color rgba="0.972549 0.529412 0.00392157 1.0" />
            </material>
        </visual>
        <collision>
            <origin xyz="0 -0.0205 0.06" rpy="-1.5708 -1.5708 0" />
            <geometry>
                <mesh filename="package:///arm4.stl" />
            </geometry>
            <material name="arm4_material">
                <color rgba="0.972549 0.529412 0.00392157 1.0" />
            </material>
        </collision>
        <inertial>
            <origin xyz="-0.0130017 3.46945e-18 -0.0385551" rpy="0 0 0" />
            <mass value="0.304573" />
            <inertia ixx="0.000140255" ixy="-1.2435e-22" ixz="1.36899e-06" iyy="0.000182801" iyz="8.63543e-24" izz="6.25553e-05" />
        </inertial>
    </link>

    <link name="arm3_3">
        <visual>
            <origin xyz="0.115 0 0.037" rpy="-3.14159 8.61933e-18 -1.20186e-17" />
            <geometry>
                <mesh filename="package:///arm3.stl" />
            </geometry>
            <material name="arm3_material">
                <color rgba="0.231373 0.380392 0.705882 1.0" />
            </material>
        </visual>
        <collision>
            <origin xyz="0.115 0 0.037" rpy="-3.14159 8.61933e-18 -1.20186e-17" />
            <geometry>
                <mesh filename="package:///arm3.stl" />
            </geometry>
            <material name="arm3_material">
                <color rgba="0.231373 0.380392 0.705882 1.0" />
            </material>
        </collision>
        <inertial>
            <origin xyz="0.0164728 -0.0533065 0.0165" rpy="0 0 0" />
            <mass value="0.253495" />
            <inertia ixx="0.000378964" ixy="0.000135069" ixz="1.43416e-21" iyy="0.00020759" iyz="-5.39346e-21" izz="0.000429282" />
        </inertial>
    </link>

    <link name="arm2_3">
        <visual>
            <origin xyz="0.0633934 -0.0959494 -0.036" rpy="2.24541e-19 8.594e-18 -1.7322e-17" />
            <geometry>
                <mesh filename="package:///arm2.stl" />
            </geometry>
            <material name="arm2_material">
                <color rgba="0.768627 0.886275 0.952941 1.0" />
            </material>
        </visual>
        <collision>
            <origin xyz="0.0633934 -0.0959494 -0.036" rpy="2.24541e-19 8.594e-18 -1.7322e-17" />
            <geometry>
                <mesh filename="package:///arm2.stl" />
            </geometry>
            <material name="arm2_material">
                <color rgba="0.768627 0.886275 0.952941 1.0" />
            </material>
        </collision>
        <inertial>
            <origin xyz="0.0535692 0.0124398 -0.0155" rpy="0 0 0" />
            <mass value="0.582673" />
            <inertia ixx="0.000143067" ixy="-8.86254e-05" ixz="-2.23358e-20" iyy="0.00111301" iyz="3.52731e-21" izz="0.00114357" />
        </inertial>
    </link>

    <link name="arm1_3">
        <visual>
            <origin xyz="-0.0452202 0.106044 0.037" rpy="-3.14159 -1.54452e-17 1.18403e-17" />
            <geometry>
                <mesh filename="package:///arm1.stl" />
            </geometry>
            <material name="arm1_material">
                <color rgba="0.917647 0.917647 0.917647 1.0" />
            </material>
        </visual>
        <collision>
            <origin xyz="-0.0452202 0.106044 0.037" rpy="-3.14159 -1.54452e-17 1.18403e-17" />
            <geometry>
                <mesh filename="package:///arm1.stl" />
            </geometry>
            <material name="arm1_material">
                <color rgba="0.917647 0.917647 0.917647 1.0" />
            </material>
        </collision>
        <inertial>
            <origin xyz="0.0422881 0.0309098 0.0165" rpy="0 0 0" />
            <mass value="0.226307" />
            <inertia ixx="0.000293317" ixy="-0.000172327" ixz="2.34016e-22" iyy="0.000261614" iyz="-2.29191e-21" izz="0.000421982" />
        </inertial>
    </link>

    <joint name="31" type="revolute">
        <origin xyz="0.108614 0.0100944 0.001" rpy="-3.14159 -4.00996e-14 -0.00992027" />
        <parent link="arm2_3" />
        <child link="arm1_3" />
        <axis xyz="0 0 1" />
        <limit effort="1" velocity="20" lower="-1.0472" upper="1.0472" />
        <joint_properties friction="0.0" />
    </joint>

    <joint name="32" type="revolute">
        <origin xyz="0.0516066 -0.0959494 0.001" rpy="3.14159 -1.51203e-15 -0.346743" />
        <parent link="arm3_3" />
        <child link="arm2_3" />
        <axis xyz="0 0 1" />
        <limit effort="1" velocity="20" lower="-1.0472" upper="1.0472" />
        <joint_properties friction="0.0" />
    </joint>

    <joint name="33" type="revolute">
        <origin xyz="0 0.0165 -0.055" rpy="1.5708 -0.263979 1.5032e-15" />
        <parent link="arm4_3" />
        <child link="arm3_3" />
        <axis xyz="0 0 1" />
        <limit effort="1" velocity="20" lower="-1.5708" upper="0" />
        <joint_properties friction="0.0" />
    </joint>

    <joint name="34" type="revolute">
        <origin xyz="-0.0145 0 0.019" rpy="-1.5708 -1.54898 -1.5708" />
        <parent link="arm5_3" />
        <child link="arm4_3" />
        <axis xyz="0 0 1" />
        <limit effort="1" velocity="20" lower="-3.14159" upper="0" />
        <joint_properties friction="0.0" />
    </joint>

    <joint name="3" type="revolute">
        <origin xyz="0.0113562 -0.281642 0.51116" rpy="-3.06924 -6.3033e-16 1.5708" />
        <parent link="part_1" />
        <child link="arm5_3" />
        <axis xyz="0 0 1" />
        <limit effort="1" velocity="20" lower="0" upper="1.5708" />
        <joint_properties friction="0.0" />
    </joint>

    <link name="arm5_4">
        <visual>
            <origin xyz="0.0455 -0.0205 0.019" rpy="-1.5708 -8.01187e-32 1.19408e-32" />
            <geometry>
                <mesh filename="package:///arm5.stl" />
            </geometry>
            <material name="arm5_material">
                <color rgba="0.647059 0.647059 0.647059 1.0" />
            </material>
        </visual>
        <collision>
            <origin xyz="0.0455 -0.0205 0.019" rpy="-1.5708 -8.01187e-32 1.19408e-32" />
            <geometry>
                <mesh filename="package:///arm5.stl" />
            </geometry>
            <material name="arm5_material">
                <color rgba="0.647059 0.647059 0.647059 1.0" />
            </material>
        </collision>
        <inertial>
            <origin xyz="-0.00577778 -1.73472e-17 0.019" rpy="0 0 0" />
            <mass value="0.0156937" />
            <inertia ixx="5.06341e-06" ixy="-1.31428e-37" ixz="3.77322e-37" iyy="5.35559e-06" iyz="5.26416e-23" izz="1.92694e-06" />
        </inertial>
    </link>

    <link name="arm4_4">
        <visual>
            <origin xyz="0 -0.0205 0.06" rpy="-1.5708 -1.5708 0" />
            <geometry>
                <mesh filename="package:///arm4.stl" />
            </geometry>
            <material name="arm4_material">
                <color rgba="0.972549 0.529412 0.00392157 1.0" />
            </material>
        </visual>
        <collision>
            <origin xyz="0 -0.0205 0.06" rpy="-1.5708 -1.5708 0" />
            <geometry>
                <mesh filename="package:///arm4.stl" />
            </geometry>
            <material name="arm4_material">
                <color rgba="0.972549 0.529412 0.00392157 1.0" />
            </material>
        </collision>
        <inertial>
            <origin xyz="-0.0130017 -2.08167e-17 -0.0385551" rpy="0 0 0" />
            <mass value="0.304573" />
            <inertia ixx="0.000140255" ixy="2.06035e-22" ixz="1.36899e-06" iyy="0.000182801" iyz="2.18299e-24" izz="6.25553e-05" />
        </inertial>
    </link>

    <link name="arm3_4">
        <visual>
            <origin xyz="0.115 0 0.037" rpy="-3.14159 -1.07135e-18 8.59745e-19" />
            <geometry>
                <mesh filename="package:///arm3.stl" />
            </geometry>
            <material name="arm3_material">
                <color rgba="0.231373 0.380392 0.705882 1.0" />
            </material>
        </visual>
        <collision>
            <origin xyz="0.115 0 0.037" rpy="-3.14159 -1.07135e-18 8.59745e-19" />
            <geometry>
                <mesh filename="package:///arm3.stl" />
            </geometry>
            <material name="arm3_material">
                <color rgba="0.231373 0.380392 0.705882 1.0" />
            </material>
        </collision>
        <inertial>
            <origin xyz="0.0164728 -0.0533065 0.0165" rpy="0 0 0" />
            <mass value="0.253495" />
            <inertia ixx="0.000378964" ixy="0.000135069" ixz="-3.76626e-22" iyy="0.00020759" iyz="1.25236e-22" izz="0.000429282" />
        </inertial>
    </link>

    <link name="arm2_4">
        <visual>
            <origin xyz="0.0633934 -0.0959494 -0.036" rpy="3.28596e-19 1.84735e-18 3.62561e-17" />
            <geometry>
                <mesh filename="package:///arm2.stl" />
            </geometry>
            <material name="arm2_material">
                <color rgba="0.768627 0.886275 0.952941 1.0" />
            </material>
        </visual>
        <collision>
            <origin xyz="0.0633934 -0.0959494 -0.036" rpy="3.28596e-19 1.84735e-18 3.62561e-17" />
            <geometry>
                <mesh filename="package:///arm2.stl" />
            </geometry>
            <material name="arm2_material">
                <color rgba="0.768627 0.886275 0.952941 1.0" />
            </material>
        </collision>
        <inertial>
            <origin xyz="0.0535692 0.0124398 -0.0155" rpy="0 0 0" />
            <mass value="0.582673" />
            <inertia ixx="0.000143067" ixy="-8.86254e-05" ixz="-2.80318e-21" iyy="0.00111301" iyz="3.61765e-22" izz="0.00114357" />
        </inertial>
    </link>

    <link name="arm1_4">
        <visual>
            <origin xyz="-0.0452202 0.106044 0.037" rpy="3.14159 1.12332e-18 2.56054e-17" />
            <geometry>
                <mesh filename="package:///arm1.stl" />
            </geometry>
            <material name="arm1_material">
                <color rgba="0.917647 0.917647 0.917647 1.0" />
            </material>
        </visual>
        <collision>
            <origin xyz="-0.0452202 0.106044 0.037" rpy="3.14159 1.12332e-18 2.56054e-17" />
            <geometry>
                <mesh filename="package:///arm1.stl" />
            </geometry>
            <material name="arm1_material">
                <color rgba="0.917647 0.917647 0.917647 1.0" />
            </material>
        </collision>
        <inertial>
            <origin xyz="0.0422881 0.0309098 0.0165" rpy="0 0 0" />
            <mass value="0.226307" />
            <inertia ixx="0.000293317" ixy="-0.000172327" ixz="5.59446e-22" iyy="0.000261614" iyz="-1.77796e-22" izz="0.000421982" />
        </inertial>
    </link>

    <joint name="41" type="revolute">
        <origin xyz="0.108614 0.0100944 0.001" rpy="-3.14159 1.61357e-15 -0.937126" />
        <parent link="arm2_4" />
        <child link="arm1_4" />
        <axis xyz="0 0 1" />
        <limit effort="1" velocity="20" lower="-1.0472" upper="1.0472" />
        <joint_properties friction="0.0" />
    </joint>

    <joint name="42" type="revolute">
        <origin xyz="0.0516066 -0.0959494 0.001" rpy="3.14159 -4.84758e-15 -0.604685" />
        <parent link="arm3_4" />
        <child link="arm2_4" />
        <axis xyz="0 0 1" />
        <limit effort="1" velocity="20" lower="-1.0472" upper="1.0472" />
        <joint_properties friction="0.0" />
    </joint>

    <joint name="43" type="revolute">
        <origin xyz="0 0.0165 -0.055" rpy="1.5708 -0.0210365 2.87126e-15" />
        <parent link="arm4_4" />
        <child link="arm3_4" />
        <axis xyz="0 0 1" />
        <limit effort="1" velocity="20" lower="-1.5708" upper="0" />
        <joint_properties friction="0.0" />
    </joint>

    <joint name="44" type="revolute">
        <origin xyz="-0.0145 6.93889e-18 0.019" rpy="1.5708 -1.48278 1.5708" />
        <parent link="arm5_4" />
        <child link="arm4_4" />
        <axis xyz="0 0 1" />
        <limit effort="1" velocity="20" lower="0" upper="3.14159" />
        <joint_properties friction="0.0" />
    </joint>

    <joint name="4" type="revolute">
        <origin xyz="0.0911469 -0.281642 0.505377" rpy="-3.06924 5.82867e-16 1.5708" />
        <parent link="part_1" />
        <child link="arm5_4" />
        <axis xyz="0 0 1" />
        <limit effort="1" velocity="20" lower="-1.5708" upper="0" />
        <joint_properties friction="0.0" />
    </joint>


</robot>